tests/mediumHard/mediumHard_8.in
15
o
10 S 101 AAIE 1953 218
11 B 103 AAN 1336 212
11 B 104 GEGS 1847 930
11 S 106 HAHEOD 216 100
0 B 107 HAHEOD 753 867
12 S 108 STRA 388 302
5 S 109 AAO 1498 482
13 B 110 HAHEOD 1556 592
2 S 112 AAC 484 809
12 B 113 GORN 1612 369
14 B 114 STRA 586 602
10 B 115 CAE 492 914
12 C 113
0 B 117 GEGS 1716 147
10 B 118 AAIC 1168 27
8 B 119 DOOR 1102 632
10 S 120 FEG 441 860
5 C 109
3 S 122 AAIE 1988 736
5 C 109
5 C 109
0 S 125 AA 1182 144
1 S 126 AAIC 925 77
8 C 119
11 B 128 AAIE 913 683
7 S 129 AAC 235 978
5 B 130 GLIN 1301 425
7 S 131 AAID 102 772
7 B 132 AAID 1652 961
8 S 133 AAC 738 747
7 S 134 GORN 728 678
7 C 131
13 S 136 GORN 1179 659
5 B 137 AAM 1412 686
8 S 138 STRIPE 768 369
7 B 139 FEG 270 783
13 B 140 FEG 1268 204
2 C 112
14 C 114
13 B 143 GORN 520 377
0 C 117
14 B 145 HAHEOD 621 157
6 S 146 DOOR 1171 705
5 S 147 STRIPE 1677 368
13 B 148 AAIE 1434 552
6 S 149 AA 1520 969
10 S 150 AAID 1840 939
12 B 151 GLIN 344 287
7 B 152 AA 388 428
9 B 153 AAIN 1772 667
2 S 154 FEG 930 814
8 S 155 GLIN 1617 964
8 B 156 AAM 1583 86
7 C 152
3 C 122
3 C 122
12 S 160 AA 888 575
6 B 161 AAM 590 120
9 C 153
11 S 163 GORN 1357 787
9 C 153
4 S 165 AAN 1307 215
1 S 166 AA 199 336
11 S 167 GEGS 527 143
12 C 160
4 C 165
2 C 154
0 C 107
13 C 140
5 B 173 AAN 1717 794
4 S 174 DOOR 1146 180
12 C 113
8 B 176 AA 1042 565
7 B 177 CAE 268 470
6 B 178 AAO 733 839
4 B 179 AAIC 1704 819
10 C 118
5 S 181 DOOR 1058 121
10 C 150
12 C 151
11 B 184 GLIN 139 318
5 C 147
4 C 165
7 C 152
1 C 166
9 S 189 AAC 630 339
14 S 190 FEG 266 27
10 B 191 A 1971 943
9 B 192 AA 1980 790
12 B 193 GEGS 1979 824
2 C 112
13 C 136
10 B 196 BDD 1692 371
11 B 197 DOOR 1475 774
2 B 198 AA 844 44
12 C 193
5 S 200 CAE 1051 554
6 B 201 CAE 312 170
4 B 202 AAM 597 928
8 S 203 AAM 820 84
9 S 204 GEGS 1223 819
6 C 201
7 S 206 CAE 1834 893
11 C 197
4 C 202
13 C 148
13 B 210 GEGS 614 866
4 S 211 DOOR 824 493
11 B 212 GORN 1647 109
6 B 213 THRONE 1985 227
1 C 166
0 B 215 AA 1193 357
13 B 216 CONC 329 365
0 S 217 DOOR 411 698
1 S 218 STRIPE 642 856
11 C 103
2 C 198
0 B 221 GORN 405 887
13 S 222 GORN 1166 203
10 B 223 GLIN 1288 689
4 C 174
4 C 165
9 B 226 AAN 917 962
10 S 227 AAIC 386 496
2 C 154
10 B 229 AAC 1225 144
6 S 230 DOOR 1987 428
2 C 154
4 S 232 A 815 379
7 B 233 GORN 361 33
4 C 179
1 C 166
4 B 236 A 1337 730
1 C 126
1 B 238 THRONE 1594 382
14 S 239 AAM 959 530
14 S 240 GLIN 1394 700
14 C 239
10 B 242 AAID 1706 241
4 B 243 AAO 636 361
0 B 244 A 890 751
2 B 245 AAN 1740 860
4 C 243
13 C 136
6 C 146
3 C 122
9 C 226
1 C 218
8 B 252 AAIN 1298 725
3 C 122
0 C 215
12 S 255 BDD 659 864
3 S 256 A 1665 229
1 C 126
14 C 190
10 C 196
8 S 260 STRA 546 630
11 B 261 VIDE 1392 11
12 B 262 BDD 553 493
10 S 263 CONC 1211 193
1 S 264 DOOR 1634 646
6 C 213
6 B 266 CAE 1276 441
11 S 267 BDD 1019 71
8 B 268 DOOR 1621 718
2 S 269 AAIE 611 914
7 C 233
13 B 271 CONC 248 745
13 B 272 CONC 168 725
3 C 256
7 B 274 STRIPE 1964 896
3 B 275 AAO 1247 814
11 C 184
0 C 107
14 B 278 AAC 500 971
1 B 279 THRONE 226 419
14 B 280 BDD 398 810
10 C 101
4 S 282 FEG 1855 879
11 B 283 GORN 336 339
9 S 284 BDD 1629 728
7 S 285 GORN 1976 159
12 C 193
11 B 287 GORN 826 499
11 B 288 STRIPE 409 780
7 S 289 CONC 747 671
7 B 290 AAO 206 225
1 S 291 AAM 155 981
7 S 292 GORN 1608 30
2 C 154
6 S 294 AAIN 1320 747
8 B 295 VIDE 369 160
4 S 296 STRA 787 669
12 S 297 AAN 1083 602
0 S 298 GORN 1598 587
6 B 299 GORN 1272 476
7 C 285
8 S 301 CONC 1490 997
5 C 130
1 C 218
6 S 304 A 601 851
2 S 305 CONC 1283 423
1 S 306 HAHEOD 345 328
3 C 275
9 B 308 AAIE 2000 263
4 B 309 STRA 853 781
6 S 310 VIDE 998 912
0 C 298
9 B 312 GORN 379 214
10 C 150
11 B 314 STRA 1701 836
12 S 315 HAHEOD 404 613
8 C 176
5 S 317 DOOR 609 100
14 C 278
4 S 319 CAE 573 425
11 S 320 STRIPE 1932 109
11 C 197
12 C 193
13 C 143
7 C 289
5 B 325 AAM 564 737
4 B 326 STRA 322 69
13 C 143
7 S 328 AAO 1287 975
10 S 329 VIDE 1877 976
11 S 330 DOOR 1742 397
5 S 331 GORN 749 316
2 S 332 CONC 179 515
0 C 107
7 S 334 AAN 412 33
13 S 335 A 762 872
9 C 308
0 C 217
8 C 203
9 C 308
2 B 340 BDD 1773 545
1 S 341 AAIE 334 887
4 C 282
11 S 343 THRONE 1859 172
8 C 252
7 S 345 THRONE 662 814
2 B 346 STRA 193 894
14 C 190
13 C 143
13 B 349 AAM 464 871
5 B 350 GLIN 1993 947
3 C 275
7 S 352 DOOR 1383 271
3 S 353 AAIC 1783 793
11 S 354 AAM 1128 874
9 C 189
10 B 356 GORN 1028 898
1 B 357 AAIC 754 927
10 S 358 HAHEOD 1850 949
2 C 305
3 S 360 AAM 1848 953
5 C 181
9 S 362 GLIN 1745 628
10 S 363 HAHEOD 858 323
11 C 103
6 C 149
14 S 366 VIDE 920 224
1 C 238
12 C 160
10 C 227
7 S 370 AAID 855 693
6 B 371 BDD 930 571
14 S 372 THRONE 1289 381
0 B 373 BDD 745 951
3 B 374 DOOR 874 153
0 S 375 VIDE 103 606
2 B 376 VIDE 189 519
4 S 377 CONC 1523 679
3 B 378 AAIE 808 886
4 S 379 AAM 1096 843
1 C 166
6 C 299
6 S 382 FEG 1875 313
12 C 255
8 B 384 GEGS 1216 911
13 B 385 VIDE 1558 712
1 S 386 A 900 333
1 C 306
0 S 388 AA 1552 51
1 S 389 AAIC 1584 289
9 C 189
9 B 391 GEGS 589 781
12 S 392 GORN 981 242
13 S 393 THRONE 793 441
8 C 155
5 S 395 VIDE 1043 69
9 S 396 AAO 674 401
6 C 299
12 B 398 GEGS 696 864
2 C 332
8 C 295
11 S 401 FEG 735 421
8 S 402 DOOR 398 283
7 S 403 HAHEOD 1134 283
13 C 335
9 C 189
13 B 406 DOOR 1089 174
6 S 407 THRONE 1043 712
8 B 408 AAIC 649 884
10 S 409 GLIN 1659 258
10 S 410 AA 552 877
14 C 145
8 B 412 VIDE 1591 116
2 C 346
12 B 414 STRIPE 1083 195
3 B 415 AAC 874 211
10 C 150
14 C 280
10 B 418 GORN 1849 298
9 S 419 THRONE 821 844
8 C 301
4 C 232
10 S 422 AAIE 651 487
10 C 410
3 S 424 FEG 142 202
10 B 425 HAHEOD 1388 287
7 C 370
2 B 427 AAIN 415 749
0 B 428 AAC 1533 852
13 C 216
3 C 415
3 C 374
0 S 432 AA 1860 111
6 C 299
14 B 434 AAIE 1370 328
8 B 435 GORN 1962 50
13 S 436 VIDE 976 883
9 C 226
4 S 438 AAID 1581 813
13 C 349
5 C 181
9 B 441 THRONE 1355 358
3 S 442 A 403 812
2 B 443 CAE 1955 173
0 S 444 GLIN 1468 315
3 B 445 AAIN 779 770
9 C 204
6 B 447 AAIC 584 523
8 S 448 AAO 1931 163
3 S 449 STRA 1617 80
10 B 450 FEG 1926 769
4 S 451 GORN 911 538
12 C 113
8 C 408
6 B 454 STRIPE 384 757
7 S 455 BDD 643 566
10 B 456 AAN 1969 75
3 B 457 AA 1255 200
6 S 458 GLIN 564 281
10 C 450
7 B 460 AAIE 200 45
11 S 461 STRIPE 2000 335
12 S 462 CONC 1180 878
9 C 308
0 C 428
4 B 465 AAID 1220 836
7 B 466 STRIPE 586 816
2 C 154
7 C 132
2 C 340
4 C 309
4 S 471 FEG 824 642
4 B 472 CAE 688 204
2 C 332
2 B 474 GORN 1029 79
10 B 475 GEGS 1710 782
10 C 363
13 S 477 GORN 1837 940
13 B 478 VIDE 1401 873
2 S 479 STRA 308 490
3 S 480 GLIN 911 644
6 B 481 FEG 1328 20
1 S 482 CONC 1223 985
2 B 483 A 1678 702
9 B 484 AAIN 1627 855
6 C 299
8 S 486 A 1324 80
0 B 487 CONC 801 464
1 S 488 GLIN 1722 102
2 B 489 FEG 520 660
1 S 490 BDD 1104 313
10 S 491 AA 733 733
13 B 492 GORN 772 940
12 C 262
14 S 494 CAE 1835 888
7 C 289
0 C 373
13 B 497 VIDE 1644 966
9 B 498 DOOR 1537 116
7 S 499 AAN 444 826
14 C 190
2 B 501 AAID 1514 539
13 S 502 AAM 942 267
0 B 503 DOOR 1418 819
9 S 504 A 471 17
8 S 505 CAE 158 138
5 S 506 AAIC 1286 859
3 S 507 BDD 125 246
4 S 508 AAM 683 780
2 C 489
9 S 510 THRONE 535 607
0 B 511 AAIC 1308 652
7 S 512 AA 544 394
9 S 513 AAIC 941 393
0 B 514 AAIE 613 688
13 B 515 THRONE 1665 286
7 S 516 BDD 1904 612
14 S 517 AAO 1327 891
4 B 518 VIDE 1690 624
9 C 504
10 B 520 FEG 231 980
0 B 521 AA 1251 447
11 C 287
6 S 523 FEG 739 853
5 C 200
10 C 242
10 C 223
8 C 260
11 S 528 AAM 855 241
10 S 529 GEGS 1622 512
5 B 530 AAIE 1494 260
10 C 329
13 S 532 CONC 949 295
9 B 533 HAHEOD 141 794
14 S 534 HAHEOD 248 267
11 C 212
9 S 536 CONC 309 436
12 C 462
5 S 538 GLIN 199 945
2 S 539 GORN 423 143
2 C 154
3 B 541 STRA 536 66
2 S 542 THRONE 1305 458
11 S 543 FEG 1833 878
14 S 544 AAM 1233 68
0 B 545 AAM 1292 516
8 C 384
10 S 547 AAN 542 80
7 B 548 DOOR 1123 651
2 C 501
3 B 550 AAIN 1552 498
2 C 539
3 B 552 GLIN 1682 387
11 C 167
0 B 554 STRA 1691 438
12 S 555 GORN 888 832
3 S 556 AAIC 1242 686
9 C 284
12 B 558 GORN 1070 791
3 S 559 FEG 421 190
3 B 560 AAID 559 418
10 S 561 GEGS 529 897
5 C 181
6 S 563 AAC 736 984
9 C 204
5 B 565 VIDE 353 732
6 B 566 DOOR 1271 328
8 C 155
3 C 556
7 S 569 AAIE 1480 635
12 S 570 DOOR 873 614
5 S 571 CAE 1033 149
10 C 242
2 C 376
9 C 362
