tests/mediumHard/mediumHard_80.in
15
o
4 B 101 A 843 561
4 S 102 GLIN 1485 682
14 S 104 AAIN 1474 295
14 C 104
0 S 108 VIDE 1635 631
12 S 109 AAC 1103 980
11 S 111 AAC 1866 990
4 B 114 GEGS 1674 720
11 C 111
1 B 116 BDD 1902 192
1 B 117 GORN 190 280
0 C 108
11 S 121 AAO 1269 862
8 B 122 FEG 1198 174
4 B 123 AAIC 1937 206
3 S 124 AAC 192 825
1 C 116
12 S 126 CAE 849 23
8 S 127 THRONE 1890 732
3 S 128 AAN 1133 194
2 B 130 GORN 1489 367
12 S 131 A 122 70
4 S 132 AA 1303 652
4 C 123
5 B 134 AAIN 960 396
5 C 134
5 C 134
9 B 138 FEG 780 975
8 S 139 GEGS 1239 609
12 B 140 AAC 1957 724
3 S 141 STRIPE 1452 482
1 C 116
11 B 143 HAHEOD 445 699
14 C 104
13 B 147 GEGS 1606 981
7 B 148 AAC 1032 33
7 B 149 AAID 672 92
1 C 116
13 S 151 HAHEOD 859 825
0 S 152 AAIE 1129 744
1 S 153 AA 240 543
0 C 152
12 C 140
5 S 156 DOOR 1282 723
11 S 157 BDD 214 699
8 B 158 HAHEOD 647 552
2 C 130
9 C 138
5 S 161 AAIN 1760 169
8 B 162 GLIN 1034 709
14 C 104
3 B 164 AAIN 1733 826
1 B 165 BDD 1089 933
7 C 149
1 C 165
5 B 168 GORN 250 578
11 S 169 GLIN 240 468
10 B 170 AA 1478 851
0 C 152
12 B 172 A 851 387
12 C 126
8 S 174 AAIE 1314 391
4 S 175 STRA 506 316
7 B 176 GEGS 1740 902
10 B 177 FEG 257 124
3 C 164
9 S 179 HAHEOD 519 637
9 S 180 AA 1486 686
0 B 181 THRONE 1385 513
13 C 151
11 C 157
10 C 177
0 S 185 AAIE 763 19
0 S 186 AA 1891 808
12 C 109
14 S 188 CONC 661 579
4 C 114
2 B 190 AAN 1245 135
14 S 191 AAIE 1292 852
1 C 116
11 S 193 AAIN 508 871
11 C 193
3 B 195 AAIC 916 355
4 S 196 AAIC 1976 934
5 B 197 AAM 987 832
14 C 104
14 S 199 AAO 313 343
7 B 200 AAIC 1438 680
13 C 147
5 B 202 AA 1759 332
2 B 203 GLIN 852 208
6 S 204 AAN 1585 687
2 C 203
6 C 204
10 C 170
11 B 208 GORN 1432 217
13 B 209 CAE 1265 351
5 C 168
0 B 211 CONC 1921 265
4 C 101
9 B 213 STRA 939 960
7 B 214 BDD 685 612
0 B 215 AA 421 312
5 S 216 FEG 373 328
9 S 217 HAHEOD 780 608
11 S 218 VIDE 1096 223
4 C 123
14 C 104
8 S 221 FEG 749 229
8 C 158
14 S 223 CONC 1545 597
11 S 224 AAN 746 943
9 S 225 STRA 203 203
0 S 226 GLIN 1405 476
10 C 177
13 S 228 AAIE 152 954
8 B 229 BDD 504 458
2 S 230 GLIN 1071 747
12 B 231 CAE 646 866
12 C 109
9 B 233 GLIN 686 675
1 B 234 GEGS 1801 425
8 S 235 CAE 248 846
8 C 127
2 C 190
2 C 203
2 B 239 THRONE 1280 481
1 S 240 THRONE 1682 199
11 C 157
9 B 242 FEG 268 115
8 S 243 AAC 917 989
8 S 244 AAIC 796 706
8 B 245 GLIN 726 90
9 C 138
10 S 247 AAO 1765 390
14 S 248 AAIC 1867 192
5 S 249 AAC 522 496
7 B 250 AAIE 799 945
6 C 204
13 C 147
1 S 253 AAIN 1541 861
0 C 152
9 S 255 GORN 935 378
2 C 203
9 S 257 VIDE 1525 648
14 B 258 AAM 1983 144
10 S 259 GORN 1637 84
9 C 255
13 C 147
11 C 218
11 C 169
12 S 264 AAIN 363 502
1 S 265 AAC 1732 171
8 B 266 AAIC 186 728
13 C 209
3 C 195
9 S 269 VIDE 182 727
1 C 165
9 S 271 HAHEOD 1252 669
3 B 272 DOOR 1609 731
14 S 273 STRIPE 459 177
13 S 274 AAO 866 805
2 S 275 STRA 377 416
11 C 169
3 C 128
1 S 278 BDD 158 894
1 C 265
14 B 280 HAHEOD 1893 678
11 S 281 AAC 1720 807
1 B 282 CAE 1059 429
8 S 283 AAC 875 163
5 B 284 AAID 164 939
11 C 193
11 B 286 AAID 1462 321
1 B 287 THRONE 969 876
10 S 288 GEGS 613 809
10 C 259
6 B 290 BDD 467 277
3 C 141
11 B 292 GLIN 976 471
5 B 293 HAHEOD 1409 391
5 S 294 FEG 447 805
2 C 239
0 C 215
5 S 297 HAHEOD 334 954
10 S 298 GORN 1401 294
7 B 299 AA 1718 454
7 C 200
5 B 301 GLIN 1910 502
6 C 290
14 C 258
13 S 304 CAE 1874 827
3 C 141
3 S 306 DOOR 693 446
8 S 307 AAID 1378 322
3 C 306
7 C 214
2 S 310 AAIN 1159 477
14 S 311 FEG 1748 344
14 S 312 AAO 1869 501
0 B 313 GORN 1243 592
7 C 299
14 B 315 CONC 1195 74
8 B 316 GLIN 1220 747
7 B 317 STRA 988 540
5 S 318 STRA 1970 522
14 C 191
0 B 320 GORN 493 788
12 B 321 GORN 616 939
1 S 322 AAIE 1718 738
9 S 323 HAHEOD 237 681
8 S 324 AAO 677 312
12 B 325 GORN 1187 11
12 C 140
11 S 327 A 867 880
14 C 199
6 B 329 HAHEOD 353 991
13 C 304
11 B 331 GORN 1093 908
11 S 332 VIDE 212 664
14 B 333 CONC 742 287
9 B 334 AA 374 11
3 B 335 AA 1929 231
1 S 336 AAID 612 427
3 C 124
2 C 275
9 C 213
1 S 340 BDD 1987 498
12 C 126
8 C 235
8 C 229
1 S 344 DOOR 866 244
3 B 345 AAC 822 42
12 C 325
2 C 190
13 B 348 AAID 342 385
11 S 349 AAC 397 765
11 S 350 GLIN 625 688
8 C 221
10 B 352 AAO 1535 649
6 C 329
5 B 354 A 569 422
9 C 242
3 B 356 STRA 1897 206
14 C 188
10 B 358 GEGS 789 777
11 C 143
7 S 360 AAN 1431 219
6 B 361 AAM 1392 616
8 B 362 AAIN 694 551
13 C 228
13 C 348
7 B 365 AAC 440 577
3 B 366 A 799 402
8 S 367 GEGS 1116 228
4 S 368 GEGS 1533 576
12 B 369 AAIC 1736 301
10 S 370 AAM 1929 916
11 S 371 AAID 1679 246
3 S 372 GEGS 744 680
8 C 362
2 C 239
3 S 375 GEGS 742 19
9 S 376 CAE 1230 988
4 B 377 STRIPE 470 863
14 B 378 AAN 1405 992
14 S 379 GORN 724 969
1 B 380 STRA 528 234
14 S 381 AAIN 181 84
14 S 382 GEGS 288 11
11 B 383 AAID 1362 821
6 C 204
13 C 147
8 C 362
3 S 387 THRONE 997 926
9 C 233
5 B 389 AAID 293 525
12 B 390 HAHEOD 857 183
8 C 127
11 S 392 STRIPE 427 322
10 S 393 DOOR 1317 755
11 C 327
8 S 395 FEG 970 640
8 C 235
0 S 397 HAHEOD 1811 253
9 B 398 GEGS 1990 982
13 S 399 GORN 1205 788
13 C 228
2 C 130
4 C 196
7 S 403 HAHEOD 1828 848
11 C 111
0 B 405 AAIN 784 195
3 C 375
14 C 333
10 C 352
0 C 181
1 C 340
2 S 411 AAM 660 694
12 C 140
7 S 413 AAIC 1715 771
11 B 414 STRIPE 1591 692
9 B 415 A 1280 414
7 B 416 GLIN 775 768
2 C 411
3 S 418 VIDE 1075 87
12 B 419 AAIC 1218 750
0 B 420 AAM 926 126
6 S 421 CAE 775 973
3 B 422 VIDE 620 11
11 B 423 DOOR 1420 469
12 S 424 STRIPE 516 851
2 C 411
8 B 426 FEG 1475 525
3 C 124
7 C 148
13 B 429 CAE 923 391
0 B 430 GLIN 1368 451
4 B 431 DOOR 421 614
4 C 368
5 B 433 AAC 1269 453
6 C 421
4 S 435 AAN 1456 896
11 S 436 HAHEOD 1809 653
0 C 181
6 S 438 GLIN 1853 787
13 S 439 AAIN 1350 990
2 C 190
10 C 370
12 C 172
8 C 367
8 S 444 GORN 817 14
5 S 445 AAN 1803 903
1 C 287
0 S 447 AAIN 1964 76
14 S 448 STRIPE 1125 559
7 B 449 AAM 1239 973
7 S 450 BDD 923 945
9 B 451 CAE 250 276
7 C 413
3 S 453 AAIE 1956 821
3 S 454 VIDE 1262 918
7 B 455 AAC 1449 990
6 B 456 DOOR 100 759
5 S 457 GORN 190 932
11 C 208
1 B 459 GORN 389 520
7 S 460 GLIN 546 390
12 S 461 BDD 1829 386
1 C 265
0 C 215
5 S 464 THRONE 1612 729
1 C 253
10 S 466 VIDE 742 379
8 S 467 VIDE 1049 34
0 S 468 DOOR 1166 646
12 S 469 CONC 1609 967
8 S 470 HAHEOD 213 736
3 S 471 THRONE 753 349
1 C 380
2 B 473 HAHEOD 1191 871
6 B 474 AAIC 979 181
7 B 475 AAC 1327 639
3 C 454
8 C 307
6 S 478 AAID 675 17
1 S 479 A 185 183
7 S 480 STRA 1760 709
0 B 481 VIDE 1981 469
6 S 482 GLIN 1528 995
13 C 209
14 C 223
12 S 485 GLIN 1120 942
8 S 486 AAM 1670 319
4 S 487 GLIN 1698 933
3 S 488 BDD 1327 854
14 C 273
12 C 419
3 S 491 CAE 735 916
8 C 307
0 S 493 AAID 419 233
7 S 494 FEG 1193 623
14 S 495 AAO 1155 57
11 C 331
5 B 497 GEGS 1401 977
11 S 498 CAE 549 765
3 C 491
13 C 228
9 C 255
1 S 502 STRA 704 859
14 S 503 STRIPE 744 949
14 S 504 AAO 1878 364
8 S 505 GLIN 1490 810
5 S 506 HAHEOD 335 783
8 S 507 HAHEOD 1745 416
0 S 508 GORN 852 167
6 C 438
11 B 510 A 1231 988
13 S 511 AA 1358 669
9 C 255
9 S 513 CAE 1158 309
7 S 514 AAM 971 690
7 B 515 AAIE 1550 19
12 S 516 AAO 1872 17
1 B 517 A 1931 122
3 C 375
9 S 519 AAN 1479 829
1 S 520 AAIE 1682 690
0 S 521 GORN 196 277
14 B 522 HAHEOD 1034 711
8 B 523 CONC 1919 647
11 S 524 A 720 559
9 S 525 GORN 1063 412
4 S 526 VIDE 222 898
7 C 455
6 B 528 AAIC 1283 182
14 S 529 GORN 194 509
8 S 530 HAHEOD 641 546
1 C 240
6 S 532 AAM 845 688
6 B 533 CONC 1588 413
6 B 534 STRIPE 137 813
12 B 535 BDD 1912 933
13 B 536 VIDE 550 389
2 S 537 BDD 284 966
14 C 258
10 S 539 STRIPE 520 477
8 S 540 STRA 252 253
8 S 541 VIDE 1442 283
2 C 473
14 C 199
4 C 175
0 C 430
7 B 546 A 1368 632
7 C 360
12 B 548 FEG 1379 348
3 S 549 AAO 1965 728
8 B 550 GORN 1319 585
9 C 233
2 B 552 STRA 133 736
12 S 553 CAE 237 749
7 B 554 AAID 1735 851
14 B 555 AAO 1146 685
10 C 393
7 S 557 STRA 814 692
2 B 558 CONC 1300 300
1 S 559 AAO 211 574
3 C 422
7 B 561 GEGS 1498 549
12 S 562 GORN 269 331
12 C 321
9 B 564 GEGS 1343 95
11 B 565 AAN 1912 728
0 C 152
1 B 567 CONC 117 23
6 B 568 DOOR 107 865
4 B 569 GORN 1079 437
7 B 570 GLIN 223 683
5 C 464
12 B 572 BDD 1295 916
8 S 573 AAIC 1199 207
7 S 574 BDD 1637 757
9 B 575 GORN 229 345
8 S 576 CAE 607 517
2 C 537
14 S 578 AAO 996 734
7 B 579 CONC 885 519
